Workbook
Name \0: #REF!
Name \0: #REF!
Name \0: #REF!
Name \0: #REF!
Name \0: #REF!
Name _FY2018: #REF!
Name _FY2018: #REF!
Name _FY2018: #REF!
Name _FY2018: #REF!
Name _FY2018: #REF!
Name _FY2019: #REF!
Name _FY2019: #REF!
Name _FY2019: #REF!
Name _FY2019: #REF!
Name _FY2019: #REF!
Name _FY2020: #REF!
Name _FY2020: #REF!
Name _FY2020: #REF!
Name _FY2020: #REF!
Name _FY2020: #REF!
Name _FY2021: #REF!
Name Adjustment: '[1]Do not Edit'!$D$4:$D$6
Name Admin: '[2]MC Assumptions'!$B$5
Name alldata: #REF!
Name alldata: #REF!
Name alldata: #REF!
Name alldata: #REF!
Name alldata: #REF!
Name alled: #REF!
Name alled: #REF!
Name alled: #REF!
Name alled: #REF!
Name alled: #REF!
Name allstem: #REF!
Name allstem: #REF!
Name allstem: #REF!
Name allstem: #REF!
Name allstem: #REF!
Name HARDCOPY: #REF!
Name Modifier: '[1]Do not Edit'!$J$4:$J$46
Name Modifier1: '[1]Do not Edit'!$G$4:$G$5
Name Modifier3: '[1]Do not Edit'!$I$4:$I$8
Name OffsetValue: #REF!
Name OffsetValue: #REF!
Name OffsetValue: #REF!
Name OffsetValue: #REF!
Name OffsetValue: #REF!
Name OffsetValue: #REF!
Name Place: '[3]Do not Edit'!$J$2:$J$9
Name PremiumTax: '[2]MC Assumptions'!$B$4
Name RiskMargin: '[2]MC Assumptions'!$B$3
Name sheet1: #REF!
Name sheet1: #REF!
Name sheet1: #REF!
Name sheet1: #REF!
Name sheet1: #REF!
Name UP: #REF!
Name UP: #REF!
Name UP: #REF!
Name UPDATE: #REF!

Sheet Fiscal by Program
A1: Updated on 2/7/2025
A2: Texas Health and Human Services Commission
A3: Provider Finance Department
A4: PERSONAL ATTENDANT BASE WAGE FISCAL ESTIMATE CALCULATOR
A5: 2026-2027 BIENNIUM
A7: Target Hourly Wage | B7: 10.6 | D7: Change the value in the highlighted cell to the left to see how service rates at a particular target wage affect fiscal outcomes.
A8: Target Payroll Taxes and Benefits Percentage for All Community Care Attendants | B8: 0.1075 | D8: Change the value in the highlighted cell to the left to see how service rates at a particular target wage affect fiscal outcomes.
A9: Target Payroll Taxes and Benefits Percentage for All Facility Based Attendants | B9: 0.1075 | D9: Change the value in the highlighted cell to the left to see how service rates at a particular target wage affect fiscal outcomes.
J10: 3-3-3-3
A11: (!) Table below will show Fiscal Impact based on the selected Target Hourly Wage set above. A change in the total estimated fiscal impact depends on which services are impacted.
A13: Notes:
A14: * Intervener services under DBMD are excluded from the fiscal impact because the services are not listed within Title 1 of the Texas Administrative Code §355.7051, Base Wage for a Personal Attendant. The Intervener services are provided by interpreters and not personal attendants.
A15: ** ICF/IID is not considered a community attendant service. It is added to the bottom of this table for informational purposes and is not included in the Total Community Attendant Fiscal Impact. A total fiscal impact that includes the community attendant and ICF/IID fiscal estimate is provided at the bottom of the this document.
A17: Service Category | B17: SFY 2026 | E17: SFY 2027 | H17: Estimated Attendant Hours
B18: AF | C18: FF | D18: GR | E18: AF | F18: FF | G18: GR | H18: SFY 2026 | I18: SFY 2027
A19: COMMUNITY ATTENDANT TOTAL FISCAL IMPACT | B19: =B117 -> 0 | C19: =C117 -> 0 | D19: =D117 -> 0 | E19: =E117 -> 0 | F19: =F117 -> 0 | G19: =G117 -> 0 | H19: =H117 -> 0 | I19: =I117 -> 0
A20: Fiscal Impact breakdown by Program and Service Category is below as follows:
A21: Community Living Assistance & Support Services Waiver (CLASS)
A22: Employment Assistance and Supported Employment | B22: =SUMIFS('Fiscal Calculation'!AO:AO,'Fiscal Calculation'!J:J,'Fiscal by Program'!$J22) -> 0 | C22: =B22-D22 -> 0 | D22: =SUMIFS('Fiscal Calculation'!AP:AP,'Fiscal Calculation'!J:J,'Fiscal by Program'!$J22) -> 0 | E22: =SUMIFS('Fiscal Calculation'!AQ:AQ,'Fiscal Calculation'!J:J,'Fiscal by Program'!$J22) -> 0 | F22: =E22-G22 -> 0 | G22: =SUMIFS('Fiscal Calculation'!AR:AR,'Fiscal Calculation'!J:J,'Fiscal by Program'!$J22) -> 0 | H22: =IF(B22>0,SUMIFS('Fiscal Calculation'!AM:AM,'Fiscal Calculation'!J:J,'Fiscal by Program'!$J22),"") | I22: =IF(E22>0,SUMIFS('Fiscal Calculation'!AN:AN,'Fiscal Calculation'!J:J,'Fiscal by Program'!$J22),"") | J22: {=INDEX('Rate Table Service Desc XWalk'!F:F,MATCH(1,(A22='Rate Table Service Desc XWalk'!B:B)*("CLASS"='Rate Table Service Desc XWalk'!A:A),0))} -> 1-1-23
A23: Habilitation | B23: =SUMIFS('Fiscal Calculation'!AO:AO,'Fiscal Calculation'!J:J,'Fiscal by Program'!$J23) -> 0 | C23: =B23-D23 -> 0 | D23: =SUMIFS('Fiscal Calculation'!AP:AP,'Fiscal Calculation'!J:J,'Fiscal by Program'!$J23) -> 0 | E23: =SUMIFS('Fiscal Calculation'!AQ:AQ,'Fiscal Calculation'!J:J,'Fiscal by Program'!$J23) -> 0 | F23: =E23-G23 -> 0 | G23: =SUMIFS('Fiscal Calculation'!AR:AR,'Fiscal Calculation'!J:J,'Fiscal by Program'!$J23) -> 0 | H23: =IF(B23>0,SUMIFS('Fiscal Calculation'!AM:AM,'Fiscal Calculation'!J:J,'Fiscal by Program'!$J23),"") | I23: =IF(E23>0,SUMIFS('Fiscal Calculation'!AN:AN,'Fiscal Calculation'!J:J,'Fiscal by Program'!$J23),"") | J23: {=INDEX('Rate Table Service Desc XWalk'!F:F,MATCH(1,(A23='Rate Table Service Desc XWalk'!B:B)*("CLASS"='Rate Table Service Desc XWalk'!A:A),0))} -> 1-1-26
A24: In Home Respite | B24: =SUMIFS('Fiscal Calculation'!AO:AO,'Fiscal Calculation'!J:J,'Fiscal by Program'!$J24) -> 0 | C24: =B24-D24 -> 0 | D24: =SUMIFS('Fiscal Calculation'!AP:AP,'Fiscal Calculation'!J:J,'Fiscal by Program'!$J24) -> 0 | E24: =SUMIFS('Fiscal Calculation'!AQ:AQ,'Fiscal Calculation'!J:J,'Fiscal by Program'!$J24) -> 0 | F24: =E24-G24 -> 0 | G24: =SUMIFS('Fiscal Calculation'!AR:AR,'Fiscal Calculation'!J:J,'Fiscal by Program'!$J24) -> 0 | H24: =IF(B24>0,SUMIFS('Fiscal Calculation'!AM:AM,'Fiscal Calculation'!J:J,'Fiscal by Program'!$J24),"") | I24: =IF(E24>0,SUMIFS('Fiscal Calculation'!AN:AN,'Fiscal Calculation'!J:J,'Fiscal by Program'!$J24),"") | J24: {=INDEX('Rate Table Service Desc XWalk'!F:F,MATCH(1,(A24='Rate Table Service Desc XWalk'!B:B)*("CLASS"='Rate Table Service Desc XWalk'!A:A),0))} -> 1-1-55
A25: PAS/HAB (CFC) | B25: =SUMIFS('Fiscal Calculation'!AO:AO,'Fiscal Calculation'!J:J,'Fiscal by Program'!$J25) -> 0 | C25: =B25-D25 -> 0 | D25: =SUMIFS('Fiscal Calculation'!AP:AP,'Fiscal Calculation'!J:J,'Fiscal by Program'!$J25) -> 0 | E25: =SUMIFS('Fiscal Calculation'!AQ:AQ,'Fiscal Calculation'!J:J,'Fiscal by Program'!$J25) -> 0 | F25: =E25-G25 -> 0 | G25: =SUMIFS('Fiscal Calculation'!AR:AR,'Fiscal Calculation'!J:J,'Fiscal by Program'!$J25) -> 0 | H25: =IF(B25>0,SUMIFS('Fiscal Calculation'!AM:AM,'Fiscal Calculation'!J:J,'Fiscal by Program'!$J25),"") | I25: =IF(E25>0,SUMIFS('Fiscal Calculation'!AN:AN,'Fiscal Calculation'!J:J,'Fiscal by Program'!$J25),"") | J25: {=INDEX('Rate Table Service Desc XWalk'!F:F,MATCH(1,(A25='Rate Table Service Desc XWalk'!B:B)*("CLASS"='Rate Table Service Desc XWalk'!A:A),0))} -> 1-1-78
A26: CDS Employment Assistance and Supported Employment | B26: =SUMIFS('Fiscal Calculation'!AO:AO,'Fiscal Calculation'!J:J,'Fiscal by Program'!$J26) -> 0 | C26: =B26-D26 -> 0 | D26: =SUMIFS('Fiscal Calculation'!AP:AP,'Fiscal Calculation'!J:J,'Fiscal by Program'!$J26) -> 0 | E26: =SUMIFS('Fiscal Calculation'!AQ:AQ,'Fiscal Calculation'!J:J,'Fiscal by Program'!$J26) -> 0 | F26: =E26-G26 -> 0 | G26: =SUMIFS('Fiscal Calculation'!AR:AR,'Fiscal Calculation'!J:J,'Fiscal by Program'!$J26) -> 0 | H26: =IF(B26>0,SUMIFS('Fiscal Calculation'!AM:AM,'Fiscal Calculation'!J:J,'Fiscal by Program'!$J26),"") | I26: =IF(E26>0,SUMIFS('Fiscal Calculation'!AN:AN,'Fiscal Calculation'!J:J,'Fiscal by Program'!$J26),"") | J26: {=INDEX('Rate Table Service Desc XWalk'!F:F,MATCH(1,(A26='Rate Table Service Desc XWalk'!B:B)*("CLASS"='Rate Table Service Desc XWalk'!A:A),0))} -> 1-5-121
A27: CDS Habilitation | B27: =SUMIFS('Fiscal Calculation'!AO:AO,'Fiscal Calculation'!J:J,'Fiscal by Program'!$J27) -> 0 | C27: =B27-D27 -> 0 | D27: =SUMIFS('Fiscal Calculation'!AP:AP,'Fiscal Calculation'!J:J,'Fiscal by Program'!$J27) -> 0 | E27: =SUMIFS('Fiscal Calculation'!AQ:AQ,'Fiscal Calculation'!J:J,'Fiscal by Program'!$J27) -> 0 | F27: =E27-G27 -> 0 | G27: =SUMIFS('Fiscal Calculation'!AR:AR,'Fiscal Calculation'!J:J,'Fiscal by Program'!$J27) -> 0 | H27: =IF(B27>0,SUMIFS('Fiscal Calculation'!AM:AM,'Fiscal Calculation'!J:J,'Fiscal by Program'!$J27),"") | I27: =IF(E27>0,SUMIFS('Fiscal Calculation'!AN:AN,'Fiscal Calculation'!J:J,'Fiscal by Program'!$J27),"") | J27: {=INDEX('Rate Table Service Desc XWalk'!F:F,MATCH(1,(A27='Rate Table Service Desc XWalk'!B:B)*("CLASS"='Rate Table Service Desc XWalk'!A:A),0))} -> 1-5-122
A28: CDS In Home Respite | B28: =SUMIFS('Fiscal Calculation'!AO:AO,'Fiscal Calculation'!J:J,'Fiscal by Program'!$J28) -> 0 | C28: =B28-D28 -> 0 | D28: =SUMIFS('Fiscal Calculation'!AP:AP,'Fiscal Calculation'!J:J,'Fiscal by Program'!$J28) -> 0 | E28: =SUMIFS('Fiscal Calculation'!AQ:AQ,'Fiscal Calculation'!J:J,'Fiscal by Program'!$J28) -> 0 | F28: =E28-G28 -> 0 | G28: =SUMIFS('Fiscal Calculation'!AR:AR,'Fiscal Calculation'!J:J,'Fiscal by Program'!$J28) -> 0 | H28: =IF(B28>0,SUMIFS('Fiscal Calculation'!AM:AM,'Fiscal Calculation'!J:J,'Fiscal by Program'!$J28),"") | I28: =IF(E28>0,SUMIFS('Fiscal Calculation'!AN:AN,'Fiscal Calculation'!J:J,'Fiscal by Program'!$J28),"") | J28: {=INDEX('Rate Table Service Desc XWalk'!F:F,MATCH(1,(A28='Rate Table Service Desc XWalk'!B:B)*("CLASS"='Rate Table Service Desc XWalk'!A:A),0))} -> 1-5-136
A29: CDS PAS/HAB (CFC) | B29: =SUMIFS('Fiscal Calculation'!AO:AO,'Fiscal Calculation'!J:J,'Fiscal by Program'!$J29) -> 0 | C29: =B29-D29 -> 0 | D29: =SUMIFS('Fiscal Calculation'!AP:AP,'Fiscal Calculation'!J:J,'Fiscal by Program'!$J29) -> 0 | E29: =SUMIFS('Fiscal Calculation'!AQ:AQ,'Fiscal Calculation'!J:J,'Fiscal by Program'!$J29) -> 0 | F29: =E29-G29 -> 0 | G29: =SUMIFS('Fiscal Calculation'!AR:AR,'Fiscal Calculation'!J:J,'Fiscal by Program'!$J29) -> 0 | H29: =IF(B29>0,SUMIFS('Fiscal Calculation'!AM:AM,'Fiscal Calculation'!J:J,'Fiscal by Program'!$J29),"") | I29: =IF(E29>0,SUMIFS('Fiscal Calculation'!AN:AN,'Fiscal Calculation'!J:J,'Fiscal by Program'!$J29),"") | J29: {=INDEX('Rate Table Service Desc XWalk'!F:F,MATCH(1,(A29='Rate Table Service Desc XWalk'!B:B)*("CLASS"='Rate Table Service Desc XWalk'!A:A),0))} -> 1-5-142
A30: CLASS Subtotal | B30: =SUM(B22:B29) -> 0 | C30: =SUM(C22:C29) -> 0 | D30: =SUM(D22:D29) -> 0 | E30: =SUM(E22:E29) -> 0 | F30: =SUM(F22:F29) -> 0 | G30: =SUM(G22:G29) -> 0 | H30: =SUM(H22:H29) -> 0 | I30: =SUM(I22:I29) -> 0
A31: Deaf-blind Multiple Disabilities Waiver (DBMD) *
A32: Assisted Living | B32: =SUMIFS('Fiscal Calculation'!AO:AO,'Fiscal Calculation'!J:J,'Fiscal by Program'!$J32) -> 0 | C32: =B32-D32 -> 0 | D32: =SUMIFS('Fiscal Calculation'!AP:AP,'Fiscal Calculation'!J:J,'Fiscal by Program'!$J32) -> 0 | E32: =SUMIFS('Fiscal Calculation'!AQ:AQ,'Fiscal Calculation'!J:J,'Fiscal by Program'!$J32) -> 0 | F32: =E32-G32 -> 0 | G32: =SUMIFS('Fiscal Calculation'!AR:AR,'Fiscal Calculation'!J:J,'Fiscal by Program'!$J32) -> 0 | H32: =IF(B32>0,SUMIFS('Fiscal Calculation'!AM:AM,'Fiscal Calculation'!J:J,'Fiscal by Program'!$J32),"") | I32: =IF(E32>0,SUMIFS('Fiscal Calculation'!AN:AN,'Fiscal Calculation'!J:J,'Fiscal by Program'!$J32),"") | J32: {=INDEX('Rate Table Service Desc XWalk'!F:F,MATCH(1,(A32='Rate Table Service Desc XWalk'!B:B)*("DBMD"='Rate Table Service Desc XWalk'!A:A),0))} -> 2-1-3
A33: Chore Services | B33: =SUMIFS('Fiscal Calculation'!AO:AO,'Fiscal Calculation'!J:J,'Fiscal by Program'!$J33) -> 0 | C33: =B33-D33 -> 0 | D33: =SUMIFS('Fiscal Calculation'!AP:AP,'Fiscal Calculation'!J:J,'Fiscal by Program'!$J33) -> 0 | E33: =SUMIFS('Fiscal Calculation'!AQ:AQ,'Fiscal Calculation'!J:J,'Fiscal by Program'!$J33) -> 0 | F33: =E33-G33 -> 0 | G33: =SUMIFS('Fiscal Calculation'!AR:AR,'Fiscal Calculation'!J:J,'Fiscal by Program'!$J33) -> 0 | H33: =IF(B33>0,SUMIFS('Fiscal Calculation'!AM:AM,'Fiscal Calculation'!J:J,'Fiscal by Program'!$J33),"") | I33: =IF(E33>0,SUMIFS('Fiscal Calculation'!AN:AN,'Fiscal Calculation'!J:J,'Fiscal by Program'!$J33),"") | J33: {=INDEX('Rate Table Service Desc XWalk'!F:F,MATCH(1,(A33='Rate Table Service Desc XWalk'!B:B)*("DBMD"='Rate Table Service Desc XWalk'!A:A),0))} -> 2-1-12
A34: Individualized Skills and Socialization - On-Site and Off-Site | B34: =SUMIFS('Fiscal Calculation'!AO:AO,'Fiscal Calculation'!J:J,'Fiscal by Program'!$J34) -> 0 | C34: =B34-D34 -> 0 | D34: =SUMIFS('Fiscal Calculation'!AP:AP,'Fiscal Calculation'!J:J,'Fiscal by Program'!$J34) -> 0 | E34: =SUMIFS('Fiscal Calculation'!AQ:AQ,'Fiscal Calculation'!J:J,'Fiscal by Program'!$J34) -> 0 | F34: =E34-G34 -> 0 | G34: =SUMIFS('Fiscal Calculation'!AR:AR,'Fiscal Calculation'!J:J,'Fiscal by Program'!$J34) -> 0 | H34: =IF(B34>0,SUMIFS('Fiscal Calculation'!AM:AM,'Fiscal Calculation'!J:J,'Fiscal by Program'!$J34),"") | I34: =IF(E34>0,SUMIFS('Fiscal Calculation'!AN:AN,'Fiscal Calculation'!J:J,'Fiscal by Program'!$J34),"") | J34: {=INDEX('Rate Table Service Desc XWalk'!F:F,MATCH(1,(A34='Rate Table Service Desc XWalk'!B:B)*("DBMD"='Rate Table Service Desc XWalk'!A:A),0))} -> 2-1-44
A35: In Home Respite | B35: =SUMIFS('Fiscal Calculation'!AO:AO,'Fiscal Calculation'!J:J,'Fiscal by Program'!$J35) -> 0 | C35: =B35-D35 -> 0 | D35: =SUMIFS('Fiscal Calculation'!AP:AP,'Fiscal Calculation'!J:J,'Fiscal by Program'!$J35) -> 0 | E35: =SUMIFS('Fiscal Calculation'!AQ:AQ,'Fiscal Calculation'!J:J,'Fiscal by Program'!$J35) -> 0 | F35: =E35-G35 -> 0 | G35: =SUMIFS('Fiscal Calculation'!AR:AR,'Fiscal Calculation'!J:J,'Fiscal by Program'!$J35) -> 0 | H35: =IF(B35>0,SUMIFS('Fiscal Calculation'!AM:AM,'Fiscal Calculation'!J:J,'Fiscal by Program'!$J35),"") | I35: =IF(E35>0,SUMIFS('Fiscal Calculation'!AN:AN,'Fiscal Calculation'!J:J,'Fiscal by Program'!$J35),"") | J35: {=INDEX('Rate Table Service Desc XWalk'!F:F,MATCH(1,(A35='Rate Table Service Desc XWalk'!B:B)*("DBMD"='Rate Table Service Desc XWalk'!A:A),0))} -> 2-1-55
A36: PAS/HAB (CFC) and Transportation | B36: =SUMIFS('Fiscal Calculation'!AO:AO,'Fiscal Calculation'!J:J,'Fiscal by Program'!$J36) -> 0 | C36: =B36-D36 -> 0 | D36: =SUMIFS('Fiscal Calculation'!AP:AP,'Fiscal Calculation'!J:J,'Fiscal by Program'!$J36) -> 0 | E36: =SUMIFS('Fiscal Calculation'!AQ:AQ,'Fiscal Calculation'!J:J,'Fiscal by Program'!$J36) -> 0 | F36: =E36-G36 -> 0 | G36: =SUMIFS('Fiscal Calculation'!AR:AR,'Fiscal Calculation'!J:J,'Fiscal by Program'!$J36) -> 0 | H36: =IF(B36>0,SUMIFS('Fiscal Calculation'!AM:AM,'Fiscal Calculation'!J:J,'Fiscal by Program'!$J36),"") | I36: =IF(E36>0,SUMIFS('Fiscal Calculation'!AN:AN,'Fiscal Calculation'!J:J,'Fiscal by Program'!$J36),"") | J36: {=INDEX('Rate Table Service Desc XWalk'!F:F,MATCH(1,(A36='Rate Table Service Desc XWalk'!B:B)*("DBMD"='Rate Table Service Desc XWalk'!A:A),0))} -> 2-1-79
A37: CDS In Home Respite | B37: =SUMIFS('Fiscal Calculation'!AO:AO,'Fiscal Calculation'!J:J,'Fiscal by Program'!$J37) -> 0 | C37: =B37-D37 -> 0 | D37: =SUMIFS('Fiscal Calculation'!AP:AP,'Fiscal Calculation'!J:J,'Fiscal by Program'!$J37) -> 0 | E37: =SUMIFS('Fiscal Calculation'!AQ:AQ,'Fiscal Calculation'!J:J,'Fiscal by Program'!$J37) -> 0 | F37: =E37-G37 -> 0 | G37: =SUMIFS('Fiscal Calculation'!AR:AR,'Fiscal Calculation'!J:J,'Fiscal by Program'!$J37) -> 0 | H37: =IF(B37>0,SUMIFS('Fiscal Calculation'!AM:AM,'Fiscal Calculation'!J:J,'Fiscal by Program'!$J37),"") | I37: =IF(E37>0,SUMIFS('Fiscal Calculation'!AN:AN,'Fiscal Calculation'!J:J,'Fiscal by Program'!$J37),"") | J37: {=INDEX('Rate Table Service Desc XWalk'!F:F,MATCH(1,(A37='Rate Table Service Desc XWalk'!B:B)*("DBMD"='Rate Table Service Desc XWalk'!A:A),0))} -> 2-5-136
A38: CDS PAS/HAB (CFC) and Transportation | B38: =SUMIFS('Fiscal Calculation'!AO:AO,'Fiscal Calculation'!J:J,'Fiscal by Program'!$J38) -> 0 | C38: =B38-D38 -> 0 | D38: =SUMIFS('Fiscal Calculation'!AP:AP,'Fiscal Calculation'!J:J,'Fiscal by Program'!$J38) -> 0 | E38: =SUMIFS('Fiscal Calculation'!AQ:AQ,'Fiscal Calculation'!J:J,'Fiscal by Program'!$J38) -> 0 | F38: =E38-G38 -> 0 | G38: =SUMIFS('Fiscal Calculation'!AR:AR,'Fiscal Calculation'!J:J,'Fiscal by Program'!$J38) -> 0 | H38: =IF(B38>0,SUMIFS('Fiscal Calculation'!AM:AM,'Fiscal Calculation'!J:J,'Fiscal by Program'!$J38),"") | I38: =IF(E38>0,SUMIFS('Fiscal Calculation'!AN:AN,'Fiscal Calculation'!J:J,'Fiscal by Program'!$J38),"") | J38: {=INDEX('Rate Table Service Desc XWalk'!F:F,MATCH(1,(A38='Rate Table Service Desc XWalk'!B:B)*("DBMD"='Rate Table Service Desc XWalk'!A:A),0))} -> 2-5-143
A39: DBMD Subtotal | B39: =SUM(B32:B38) -> 0 | C39: =SUM(C32:C38) -> 0 | D39: =SUM(D32:D38) -> 0 | E39: =SUM(E32:E38) -> 0 | F39: =SUM(F32:F38) -> 0 | G39: =SUM(G32:G38) -> 0 | H39: =SUM(H32:H38) -> 0 | I39: =SUM(I32:I38) -> 0
A40: Home and Community-Based Services Waiver (HCS)
A41: Employment Assistance and Supported Employment | B41: =SUMIFS('Fiscal Calculation'!AO:AO,'Fiscal Calculation'!J:J,'Fiscal by Program'!$J41) -> 0 | C41: =B41-D41 -> 0 | D41: =SUMIFS('Fiscal Calculation'!AP:AP,'Fiscal Calculation'!J:J,'Fiscal by Program'!$J41) -> 0 | E41: =SUMIFS('Fiscal Calculation'!AQ:AQ,'Fiscal Calculation'!J:J,'Fiscal by Program'!$J41) -> 0 | F41: =E41-G41 -> 0 | G41: =SUMIFS('Fiscal Calculation'!AR:AR,'Fiscal Calculation'!J:J,'Fiscal by Program'!$J41) -> 0 | H41: =IF(B41>0,SUMIFS('Fiscal Calculation'!AM:AM,'Fiscal Calculation'!J:J,'Fiscal by Program'!$J41),"") | I41: =IF(E41>0,SUMIFS('Fiscal Calculation'!AN:AN,'Fiscal Calculation'!J:J,'Fiscal by Program'!$J41),"") | J41: {=INDEX('Rate Table Service Desc XWalk'!F:F,MATCH(1,(A41='Rate Table Service Desc XWalk'!B:B)*("HCS"='Rate Table Service Desc XWalk'!A:A),0))} -> 3-1-23
A42: In Home Respite | B42: =SUMIFS('Fiscal Calculation'!AO:AO,'Fiscal Calculation'!J:J,'Fiscal by Program'!$J42) -> 0 | C42: =B42-D42 -> 0 | D42: =SUMIFS('Fiscal Calculation'!AP:AP,'Fiscal Calculation'!J:J,'Fiscal by Program'!$J42) -> 0 | E42: =SUMIFS('Fiscal Calculation'!AQ:AQ,'Fiscal Calculation'!J:J,'Fiscal by Program'!$J42) -> 0 | F42: =E42-G42 -> 0 | G42: =SUMIFS('Fiscal Calculation'!AR:AR,'Fiscal Calculation'!J:J,'Fiscal by Program'!$J42) -> 0 | H42: =IF(B42>0,SUMIFS('Fiscal Calculation'!AM:AM,'Fiscal Calculation'!J:J,'Fiscal by Program'!$J42),"") | I42: =IF(E42>0,SUMIFS('Fiscal Calculation'!AN:AN,'Fiscal Calculation'!J:J,'Fiscal by Program'!$J42),"") | J42: {=INDEX('Rate Table Service Desc XWalk'!F:F,MATCH(1,(A42='Rate Table Service Desc XWalk'!B:B)*("HCS"='Rate Table Service Desc XWalk'!A:A),0))} -> 3-1-39
A43: Individualized Skills and Socialization | B43: =SUMIFS('Fiscal Calculation'!AO:AO,'Fiscal Calculation'!J:J,'Fiscal by Program'!$J43) -> 0 | C43: =B43-D43 -> 0 | D43: =SUMIFS('Fiscal Calculation'!AP:AP,'Fiscal Calculation'!J:J,'Fiscal by Program'!$J43) -> 0 | E43: =SUMIFS('Fiscal Calculation'!AQ:AQ,'Fiscal Calculation'!J:J,'Fiscal by Program'!$J43) -> 0 | F43: =E43-G43 -> 0 | G43: =SUMIFS('Fiscal Calculation'!AR:AR,'Fiscal Calculation'!J:J,'Fiscal by Program'!$J43) -> 0 | H43: =IF(B43>0,SUMIFS('Fiscal Calculation'!AM:AM,'Fiscal Calculation'!J:J,'Fiscal by Program'!$J43),"") | I43: =IF(E43>0,SUMIFS('Fiscal Calculation'!AN:AN,'Fiscal Calculation'!J:J,'Fiscal by Program'!$J43),"") | J43: {=INDEX('Rate Table Service Desc XWalk'!F:F,MATCH(1,(A43='Rate Table Service Desc XWalk'!B:B)*("HCS"='Rate Table Service Desc XWalk'!A:A),0))} -> 3-1-45
...

Sheet Fiscal Calculation
A1: Formulas | AE1: =1 / (1-0.0875) -> 1.0958904 | AF1: 0 or -0.06 | AV1: FMAP AS OF April 2024 (no change to account for updated FMAP in Dec 24) | AW1: 2024 | AX1: 2025 | AY1: 2026 | AZ1: 2027 | BA1: 2028
A2: 2024 Bill Code Combo | B2: Bill Code Combo or SK with Trend | C2: Attendant Service? | D2: Facility Based | E2: Program Name | F2: Service Category | G2: RT Service Description | H2: Bill Matrix Service Description | I2: CDS | J2: Rolled Up Section /Sort/ RT Descripton ID | K2: Funding Authority | L2: Unit Measure | M2: Units | N2: Adjusted Units (CDS and ISS services) | O2: Payment | P2: Current Rate Effective Date | Q2: Current Rate | R2: Current Attendant Cost | S2: Attendant Cost % | T2: Adjusted Attendant Hours Per Unit of Service | U2: Methodological Attendant Cost Per 15 Min Increment | V2: Methodological Attendant Cost Per Unit of Service | W2: Estimated Fiscal Impact Per Unit of Services | X2: Wages Required for Fiscal Impact | Y2: Rate after Increased Wages and PTB | Z2: Factor for conversion to 15 Min increments | AA2: Attendant hours per 15 Min Unit of Service | AB2: BE Methodological Rate ID | AC2: CFC | AD2: Name of Trend | AE2: MCO Gross up (1 / (1-0.0875)) or FFS 1.0 | AF2: CFC Reduction for FMAP | AG2: Base Year Trended to 2024 | AH2: Base Year Trended to 2025 | AI2: Base Year Trended to 2026 | AJ2: Base Year Trended to 2027 | AK2: Base Year Trended to 2028 | AL2: Title XX | AM2: SFY 26 Est Att Hours | AN2: SFY 27 Est Att Hours | AO2: AF Estimated 2026 Cost | AP2: GR Estimated 2026 Cost | AQ2: AF Estimated 2027 Cost | AR2: GR Estimated 2027 Cost | AV2: Regular | AW2: 0.3987 | AX2: 0.3999 | AY2: 0.4058 | AZ2: 0.4063 | BA2: 0.4063
A3: 717DG0742 | B3: 717DG0742 | C3: Yes | D3: No | E3: CAS | F3: CAS/FC/PHC PAS | G3: =INDEX('[4]RT Description to Bill Matix'!$D:$D,MATCH(A3,'[4]RT Description to Bill Matix'!$M:$M,0)) -> CAS/FC/PAS/PHC PRIORITY | H3: PAS COMMUNITY ATTENDANT SERVICES (1929B) LVL 2 (PRIORITY) (AO) | J3: {=INDEX('Rate Table Service Desc XWalk'!F:F,MATCH(1,(G3='Rate Table Service Desc XWalk'!B:B)*(E3='Rate Table Service Desc XWalk'!A:A),0))} -> 13-1-8 | K3: =INDEX('[5]Combined Bill Code List'!$A:$A,MATCH(A3,'[5]Combined Bill Code List'!$F:$F,0)) -> State Plan (Title XIX) | L3: =INDEX('[6]Rate History'!$P:$P,MATCH(A3,'[6]Rate History'!$F:$F,0)) -> 1 hour | M3: =INDEX('[7]PDF DB Service Pivot'!$C:$C,MATCH(B3,'[7]PDF DB Service Pivot'!$B:$B,0)) -> 670573.75 | N3: =IF(ISNUMBER(FIND("ISS",F3)),IF(I3="Yes",((M3/Q3)/6)*12,(M3/6)*12),IF(AND(I3="Yes",M3=O3),M3/Q3,M3)) -> 670573.75 | O3: =INDEX('[7]PDF DB Service Pivot'!$D:$D,MATCH(B3,'[7]PDF DB Service Pivot'!$B:$B,0)) -> 8827649.8 | P3: 45170 | Q3: 14 | R3: 11.75 | S3: =_xlfn.IFNA(R3/Q3,"") -> 0.83928571 | T3: =INDEX('[8]Billable Services'!$P:$P,MATCH(A3,'[8]Billable Services'!$S:$S,0)) -> 1 | U3: =ROUND(V3/Z3,2) -> 0 | V3: {=_xlfn.IFS('Fiscal by Program'!$B$7<10.61,0,'Fiscal by Program'!$B$7>10.6,(ROUND('Fiscal by Program'!$B$7*(1+IF(D3="Yes",'Fiscal by Program'!$B$9,'Fiscal by Program'!$B$8))*T3,2)))} -> 0 | W3: =IF(V3-R3<0,0,V3-R3) -> 0 | X3: =ROUND((R3/(1+IF(D3="Yes",'Fiscal by Program'!$B$9,'Fiscal by Program'!$B$8))),2)+0.01 -> 10.62 | Y3: =Q3+W3 -> 14 | Z3: 4 | AA3: =T3/Z3 -> 0.25 | AB3: =INDEX('[9]Service List'!$K:$K,MATCH(A3,'[9]Service List'!$F:$F,0)) -> 5 | AC3: =INDEX('[5]Combined Bill Code List'!$P:$P,MATCH(A3,'[5]Combined Bill Code List'!$F:$F,0)) -> 0 | AD3: CAS | AE3: 1 | AF3: 0 | AG3: =ROUND(INDEX('All Trends'!D:D,MATCH($AD3,'All Trends'!$C:$C,0)),4) -> 0.9428 | AH3: =ROUND(INDEX('All Trends'!E:E,MATCH($AD3,'All Trends'!$C:$C,0)),4) -> 1.049 | AI3: =ROUND(INDEX('All Trends'!F:F,MATCH($AD3,'All Trends'!$C:$C,0)),4) -> 1.0459 | AJ3: =ROUND(INDEX('All Trends'!G:G,MATCH($AD3,'All Trends'!$C:$C,0)),4) -> 1.0566 | AK3: =ROUND(INDEX('All Trends'!H:H,MATCH($AD3,'All Trends'!$C:$C,0)),4) -> 1.0747 | AL3: No | AM3: =IF(C3="Yes",ROUND(T3*N3*AI3,2),0) -> 701353.09 | AN3: =IF(C3="Yes",ROUND(T3*N3*AJ3,2),0) -> 708528.22 | AO3: =IF(C3="Yes",ROUND((W3*N3*AI3),2),0) -> 0 | AP3: =IF(C3="Yes",IF($AL3="No",ROUND(($AO3*($AY$2+$AF3)),2),ROUND($AO3,2)),0) -> 0 | AQ3: =IF(C3="Yes",ROUND((W3*N3*AJ3),2),0) -> 0 | AR3: =IF(C3="Yes",IF($AL3="No",ROUND(($AQ3*($AZ$2+$AF3)),2),ROUND($AQ3,2)),0) -> 0
A4: 717DG0743 | B4: 717DG0743 | C4: Yes | D4: No | E4: CAS | F4: CAS/FC/PHC PAS | G4: =INDEX('[4]RT Description to Bill Matix'!$D:$D,MATCH(A4,'[4]RT Description to Bill Matix'!$M:$M,0)) -> CAS/FC/PAS/PHC NON-PRIORITY | H4: PAS COMMUNITY ATTENDANT SERVICES (1929B) LVL 1 (NON-PRIORITY) (AO) | J4: {=INDEX('Rate Table Service Desc XWalk'!F:F,MATCH(1,(G4='Rate Table Service Desc XWalk'!B:B)*(E4='Rate Table Service Desc XWalk'!A:A),0))} -> 13-1-7 | K4: =INDEX('[5]Combined Bill Code List'!$A:$A,MATCH(A4,'[5]Combined Bill Code List'!$F:$F,0)) -> State Plan (Title XIX) | L4: =INDEX('[6]Rate History'!$P:$P,MATCH(A4,'[6]Rate History'!$F:$F,0)) -> 1 hour | M4: =INDEX('[7]PDF DB Service Pivot'!$C:$C,MATCH(B4,'[7]PDF DB Service Pivot'!$B:$B,0)) -> 73113779 | N4: =IF(ISNUMBER(FIND("ISS",F4)),IF(I4="Yes",((M4/Q4)/6)*12,(M4/6)*12),IF(AND(I4="Yes",M4=O4),M4/Q4,M4)) -> 73113779 | O4: =INDEX('[7]PDF DB Service Pivot'!$D:$D,MATCH(B4,'[7]PDF DB Service Pivot'!$B:$B,0)) -> 9.4913459e+08 | P4: 45170 | Q4: 13.84 | R4: 11.77 | S4: =_xlfn.IFNA(R4/Q4,"") -> 0.85043353 | T4: =INDEX('[8]Billable Services'!$P:$P,MATCH(A4,'[8]Billable Services'!$S:$S,0)) -> 1 | U4: =ROUND(V4/Z4,2) -> 0 | V4: {=_xlfn.IFS('Fiscal by Program'!$B$7<10.61,0,'Fiscal by Program'!$B$7>10.6,(ROUND('Fiscal by Program'!$B$7*(1+IF(D4="Yes",'Fiscal by Program'!$B$9,'Fiscal by Program'!$B$8))*T4,2)))} -> 0 | W4: =IF(V4-R4<0,0,V4-R4) -> 0 | X4: =ROUND((R4/(1+IF(D4="Yes",'Fiscal by Program'!$B$9,'Fiscal by Program'!$B$8))),2)+0.01 -> 10.64 | Y4: =Q4+W4 -> 13.84 | Z4: 4 | AA4: =T4/Z4 -> 0.25 | AB4: =INDEX('[9]Service List'!$K:$K,MATCH(A4,'[9]Service List'!$F:$F,0)) -> 4 | AC4: =INDEX('[5]Combined Bill Code List'!$P:$P,MATCH(A4,'[5]Combined Bill Code List'!$F:$F,0)) -> 0 | AD4: CAS | AE4: 1 | AF4: 0 | AG4: =ROUND(INDEX('All Trends'!D:D,MATCH($AD4,'All Trends'!$C:$C,0)),4) -> 0.9428 | AH4: =ROUND(INDEX('All Trends'!E:E,MATCH($AD4,'All Trends'!$C:$C,0)),4) -> 1.049 | AI4: =ROUND(INDEX('All Trends'!F:F,MATCH($AD4,'All Trends'!$C:$C,0)),4) -> 1.0459 | AJ4: =ROUND(INDEX('All Trends'!G:G,MATCH($AD4,'All Trends'!$C:$C,0)),4) -> 1.0566 | AK4: =ROUND(INDEX('All Trends'!H:H,MATCH($AD4,'All Trends'!$C:$C,0)),4) -> 1.0747 | AL4: No | AM4: =IF(C4="Yes",ROUND(T4*N4*AI4,2),0) -> 76469701 | AN4: =IF(C4="Yes",ROUND(T4*N4*AJ4,2),0) -> 77252018 | AO4: =IF(C4="Yes",ROUND((W4*N4*AI4),2),0) -> 0 | AP4: =IF(C4="Yes",IF($AL4="No",ROUND(($AO4*($AY$2+$AF4)),2),ROUND($AO4,2)),0) -> 0 | AQ4: =IF(C4="Yes",ROUND((W4*N4*AJ4),2),0) -> 0 | AR4: =IF(C4="Yes",IF($AL4="No",ROUND(($AQ4*($AZ$2+$AF4)),2),ROUND($AQ4,2)),0) -> 0
A5: 717DVG0748 | B5: 717DVG0748 | C5: Yes | D5: No | E5: CAS | F5: CAS/FC/PHC PAS | G5: =INDEX('[4]RT Description to Bill Matix'!$D:$D,MATCH(A5,'[4]RT Description to Bill Matix'!$M:$M,0)) -> CDS CAS/FC/PAS/PHC PRIORITY | H5: COMMUNITY ATTENDANT SERVICES (1929B) LEVEL 2 (PRIORITY) (CDS) | I5: Yes | J5: {=INDEX('Rate Table Service Desc XWalk'!F:F,MATCH(1,(G5='Rate Table Service Desc XWalk'!B:B)*(E5='Rate Table Service Desc XWalk'!A:A),0))} -> 13-5-117 | K5: =INDEX('[5]Combined Bill Code List'!$A:$A,MATCH(A5,'[5]Combined Bill Code List'!$F:$F,0)) -> State Plan (Title XIX) | L5: =INDEX('[6]Rate History'!$P:$P,MATCH(A5,'[6]Rate History'!$F:$F,0)) -> 1 hour | M5: =INDEX('[7]PDF DB Service Pivot'!$C:$C,MATCH(B5,'[7]PDF DB Service Pivot'!$B:$B,0)) -> 149974.35 | N5: =IF(ISNUMBER(FIND("ISS",F5)),IF(I5="Yes",((M5/Q5)/6)*12,(M5/6)*12),IF(AND(I5="Yes",M5=O5),M5/Q5,M5)) -> 11361.693 | O5: =INDEX('[7]PDF DB Service Pivot'!$D:$D,MATCH(B5,'[7]PDF DB Service Pivot'!$B:$B,0)) -> 149974.35 | P5: 45170 | Q5: 13.2 | R5: 11.75 | S5: =_xlfn.IFNA(R5/Q5,"") -> 0.89015152 | T5: 1 | U5: =ROUND(V5/Z5,2) -> 0 | V5: {=_xlfn.IFS('Fiscal by Program'!$B$7<10.61,0,'Fiscal by Program'!$B$7>10.6,(ROUND('Fiscal by Program'!$B$7*(1+IF(D5="Yes",'Fiscal by Program'!$B$9,'Fiscal by Program'!$B$8))*T5,2)))} -> 0 | W5: =IF(V5-R5<0,0,V5-R5) -> 0 | X5: =ROUND((R5/(1+IF(D5="Yes",'Fiscal by Program'!$B$9,'Fiscal by Program'!$B$8))),2)+0.01 -> 10.62 | Y5: =Q5+W5 -> 13.2 | Z5: 4 | AA5: =T5/Z5 -> 0.25 | AB5: =INDEX('[9]Service List'!$K:$K,MATCH(A5,'[9]Service List'!$F:$F,0)) -> 7 | AC5: =INDEX('[5]Combined Bill Code List'!$P:$P,MATCH(A5,'[5]Combined Bill Code List'!$F:$F,0)) -> 0 | AD5: CAS | AE5: 1 | AF5: 0 | AG5: =ROUND(INDEX('All Trends'!D:D,MATCH($AD5,'All Trends'!$C:$C,0)),4) -> 0.9428 | AH5: =ROUND(INDEX('All Trends'!E:E,MATCH($AD5,'All Trends'!$C:$C,0)),4) -> 1.049 | AI5: =ROUND(INDEX('All Trends'!F:F,MATCH($AD5,'All Trends'!$C:$C,0)),4) -> 1.0459 | AJ5: =ROUND(INDEX('All Trends'!G:G,MATCH($AD5,'All Trends'!$C:$C,0)),4) -> 1.0566 | AK5: =ROUND(INDEX('All Trends'!H:H,MATCH($AD5,'All Trends'!$C:$C,0)),4) -> 1.0747 | AL5: No | AM5: =IF(C5="Yes",ROUND(T5*N5*AI5,2),0) -> 11883.19 | AN5: =IF(C5="Yes",ROUND(T5*N5*AJ5,2),0) -> 12004.77 | AO5: =IF(C5="Yes",ROUND((W5*N5*AI5),2),0) -> 0 | AP5: =IF(C5="Yes",IF($AL5="No",ROUND(($AO5*($AY$2+$AF5)),2),ROUND($AO5,2)),0) -> 0 | AQ5: =IF(C5="Yes",ROUND((W5*N5*AJ5),2),0) -> 0 | AR5: =IF(C5="Yes",IF($AL5="No",ROUND(($AQ5*($AZ$2+$AF5)),2),ROUND($AQ5,2)),0) -> 0
A6: 717DVG0749 | B6: 717DVG0749 | C6: Yes | D6: No | E6: CAS | F6: CAS/FC/PHC PAS | G6: =INDEX('[4]RT Description to Bill Matix'!$D:$D,MATCH(A6,'[4]RT Description to Bill Matix'!$M:$M,0)) -> CDS CAS/FC/PAS/PHC NON-PRIORITY | H6: COMMUNITY ATTENDANT SERVICES (1929B) LEVEL 1 (NON-PRIORITY) (CDS) | I6: Yes | J6: {=INDEX('Rate Table Service Desc XWalk'!F:F,MATCH(1,(G6='Rate Table Service Desc XWalk'!B:B)*(E6='Rate Table Service Desc XWalk'!A:A),0))} -> 13-5-116 | K6: =INDEX('[5]Combined Bill Code List'!$A:$A,MATCH(A6,'[5]Combined Bill Code List'!$F:$F,0)) -> State Plan (Title XIX) | L6: =INDEX('[6]Rate History'!$P:$P,MATCH(A6,'[6]Rate History'!$F:$F,0)) -> 1 hour | M6: =INDEX('[7]PDF DB Service Pivot'!$C:$C,MATCH(B6,'[7]PDF DB Service Pivot'!$B:$B,0)) -> 6420811.2 | N6: =IF(ISNUMBER(FIND("ISS",F6)),IF(I6="Yes",((M6/Q6)/6)*12,(M6/6)*12),IF(AND(I6="Yes",M6=O6),M6/Q6,M6)) -> 492393.5 | O6: =INDEX('[7]PDF DB Service Pivot'!$D:$D,MATCH(B6,'[7]PDF DB Service Pivot'!$B:$B,0)) -> 6420811.2 | P6: 45170 | Q6: 13.04 | R6: 11.77 | S6: =_xlfn.IFNA(R6/Q6,"") -> 0.90260736 | T6: 1 | U6: =ROUND(V6/Z6,2) -> 0 | V6: {=_xlfn.IFS('Fiscal by Program'!$B$7<10.61,0,'Fiscal by Program'!$B$7>10.6,(ROUND('Fiscal by Program'!$B$7*(1+IF(D6="Yes",'Fiscal by Program'!$B$9,'Fiscal by Program'!$B$8))*T6,2)))} -> 0 | W6: =IF(V6-R6<0,0,V6-R6) -> 0 | X6: =ROUND((R6/(1+IF(D6="Yes",'Fiscal by Program'!$B$9,'Fiscal by Program'!$B$8))),2)+0.01 -> 10.64 | Y6: =Q6+W6 -> 13.04 | Z6: 4 | AA6: =T6/Z6 -> 0.25 | AB6: =INDEX('[9]Service List'!$K:$K,MATCH(A6,'[9]Service List'!$F:$F,0)) -> 6 | AC6: =INDEX('[5]Combined Bill Code List'!$P:$P,MATCH(A6,'[5]Combined Bill Code List'!$F:$F,0)) -> 0 | AD6: CAS | AE6: 1 | AF6: 0 | AG6: =ROUND(INDEX('All Trends'!D:D,MATCH($AD6,'All Trends'!$C:$C,0)),4) -> 0.9428 | AH6: =ROUND(INDEX('All Trends'!E:E,MATCH($AD6,'All Trends'!$C:$C,0)),4) -> 1.049 | AI6: =ROUND(INDEX('All Trends'!F:F,MATCH($AD6,'All Trends'!$C:$C,0)),4) -> 1.0459 | AJ6: =ROUND(INDEX('All Trends'!G:G,MATCH($AD6,'All Trends'!$C:$C,0)),4) -> 1.0566 | AK6: =ROUND(INDEX('All Trends'!H:H,MATCH($AD6,'All Trends'!$C:$C,0)),4) -> 1.0747 | AL6: No | AM6: =IF(C6="Yes",ROUND(T6*N6*AI6,2),0) -> 514994.36 | AN6: =IF(C6="Yes",ROUND(T6*N6*AJ6,2),0) -> 520262.97 | AO6: =IF(C6="Yes",ROUND((W6*N6*AI6),2),0) -> 0 | AP6: =IF(C6="Yes",IF($AL6="No",ROUND(($AO6*($AY$2+$AF6)),2),ROUND($AO6,2)),0) -> 0 | AQ6: =IF(C6="Yes",ROUND((W6*N6*AJ6),2),0) -> 0 | AR6: =IF(C6="Yes",IF($AL6="No",ROUND(($AQ6*($AZ$2+$AF6)),2),ROUND($AQ6,2)),0) -> 0
A7: 717DVG0750 | B7: 717DVG0750 | C7: Yes | D7: No | E7: CAS | F7: CAS/FC/PHC PAS | G7: =INDEX('[4]RT Description to Bill Matix'!$D:$D,MATCH(A7,'[4]RT Description to Bill Matix'!$M:$M,0)) -> CDS CAS/FC/PAS/PHC NON-PRIORITY | H7: PAS COMMUNITY ATTENDANT SERVICES (CDS) | I7: Yes | J7: {=INDEX('Rate Table Service Desc XWalk'!F:F,MATCH(1,(G7='Rate Table Service Desc XWalk'!B:B)*(E7='Rate Table Service Desc XWalk'!A:A),0))} -> 13-5-116 | K7: =INDEX('[5]Combined Bill Code List'!$A:$A,MATCH(A7,'[5]Combined Bill Code List'!$F:$F,0)) -> State Plan (Title XIX) | L7: =INDEX('[6]Rate History'!$P:$P,MATCH(A7,'[6]Rate History'!$F:$F,0)) -> 1 hour | M7: =INDEX('[7]PDF DB Service Pivot'!$C:$C,MATCH(B7,'[7]PDF DB Service Pivot'!$B:$B,0)) -> 83175.02 | N7: =IF(ISNUMBER(FIND("ISS",F7)),IF(I7="Yes",((M7/Q7)/6)*12,(M7/6)*12),IF(AND(I7="Yes",M7=O7),M7/Q7,M7)) -> 6378.4525 | O7: =INDEX('[7]PDF DB Service Pivot'!$D:$D,MATCH(B7,'[7]PDF DB Service Pivot'!$B:$B,0)) -> 83175.02 | P7: =P6 -> 45170 | Q7: 13.04 | R7: 11.77 | S7: =_xlfn.IFNA(R7/Q7,"") -> 0.90260736 | T7: 1 | U7: =ROUND(V7/Z7,2) -> 0 | V7: {=_xlfn.IFS('Fiscal by Program'!$B$7<10.61,0,'Fiscal by Program'!$B$7>10.6,(ROUND('Fiscal by Program'!$B$7*(1+IF(D7="Yes",'Fiscal by Program'!$B$9,'Fiscal by Program'!$B$8))*T7,2)))} -> 0 | W7: =IF(V7-R7<0,0,V7-R7) -> 0 | X7: =ROUND((R7/(1+IF(D7="Yes",'Fiscal by Program'!$B$9,'Fiscal by Program'!$B$8))),2)+0.01 -> 10.64 | Y7: =Q7+W7 -> 13.04 | Z7: 4 | AA7: =T7/Z7 -> 0.25 | AB7: =INDEX('[9]Service List'!$K:$K,MATCH(A7,'[9]Service List'!$F:$F,0)) -> 1356 | AC7: =INDEX('[5]Combined Bill Code List'!$P:$P,MATCH(A7,'[5]Combined Bill Code List'!$F:$F,0)) -> 0 | AD7: CAS | AE7: 1 | AF7: 0 | AG7: =ROUND(INDEX('All Trends'!D:D,MATCH($AD7,'All Trends'!$C:$C,0)),4) -> 0.9428 | AH7: =ROUND(INDEX('All Trends'!E:E,MATCH($AD7,'All Trends'!$C:$C,0)),4) -> 1.049 | AI7: =ROUND(INDEX('All Trends'!F:F,MATCH($AD7,'All Trends'!$C:$C,0)),4) -> 1.0459 | AJ7: =ROUND(INDEX('All Trends'!G:G,MATCH($AD7,'All Trends'!$C:$C,0)),4) -> 1.0566 | AK7: =ROUND(INDEX('All Trends'!H:H,MATCH($AD7,'All Trends'!$C:$C,0)),4) -> 1.0747 | AL7: No | AM7: =IF(C7="Yes",ROUND(T7*N7*AI7,2),0) -> 6671.22 | AN7: =IF(C7="Yes",ROUND(T7*N7*AJ7,2),0) -> 6739.47 | AO7: =IF(C7="Yes",ROUND((W7*N7*AI7),2),0) -> 0 | AP7: =IF(C7="Yes",IF($AL7="No",ROUND(($AO7*($AY$2+$AF7)),2),ROUND($AO7,2)),0) -> 0 | AQ7: =IF(C7="Yes",ROUND((W7*N7*AJ7),2),0) -> 0 | AR7: =IF(C7="Yes",IF($AL7="No",ROUND(($AQ7*($AZ$2+$AF7)),2),ROUND($AQ7,2)),0) -> 0
A8: 210BS0107 | B8: 210BS0107 | C8: Yes | D8: No | E8: CLASS | F8: PAS/HAB | G8: =INDEX('[4]RT Description to Bill Matix'!$D:$D,MATCH(A8,'[4]RT Description to Bill Matix'!$M:$M,0)) -> Habilitation | H8: HABILITATION PREVOCATIONAL | J8: {=INDEX('Rate Table Service Desc XWalk'!F:F,MATCH(1,(G8='Rate Table Service Desc XWalk'!B:B)*(E8='Rate Table Service Desc XWalk'!A:A),0))} -> 1-1-26 | K8: =INDEX('[5]Combined Bill Code List'!$A:$A,MATCH(A8,'[5]Combined Bill Code List'!$F:$F,0)) -> 1915(c) waiver | L8: =INDEX('[6]Rate History'!$P:$P,MATCH(A8,'[6]Rate History'!$F:$F,0)) -> 1 hour (ceiling) | M8: =INDEX('[7]PDF DB Service Pivot'!$C:$C,MATCH(B8,'[7]PDF DB Service Pivot'!$B:$B,0)) -> 4952394.6 | N8: =O8/Q8 -> 332505.48 | O8: =INDEX('[7]PDF DB Service Pivot'!$D:$D,MATCH(B8,'[7]PDF DB Service Pivot'!$B:$B,0)) -> 4974282 | P8: 45170 | Q8: 14.96 | R8: 11.75 | S8: =_xlfn.IFNA(R8/Q8,"") -> 0.78542781 | T8: =INDEX('[8]Billable Services'!$P:$P,MATCH(B8,'[8]Billable Services'!$S:$S,0)) -> 1 | U8: =ROUND(V8/Z8,2) -> 0 | V8: {=_xlfn.IFS('Fiscal by Program'!$B$7<10.61,0,'Fiscal by Program'!$B$7>10.6,(ROUND('Fiscal by Program'!$B$7*(1+IF(D8="Yes",'Fiscal by Program'!$B$9,'Fiscal by Program'!$B$8))*T8,2)))} -> 0 | W8: =IF(V8-R8<0,0,V8-R8) -> 0 | X8: =ROUND((R8/(1+IF(D8="Yes",'Fiscal by Program'!$B$9,'Fiscal by Program'!$B$8))),2)+0.01 -> 10.62 | Y8: =Q8+W8 -> 14.96 | Z8: 4 | AA8: =T8/Z8 -> 0.25 | AB8: =INDEX('[9]Service List'!$K:$K,MATCH(A8,'[9]Service List'!$F:$F,0)) -> 36 | AC8: =INDEX('[5]Combined Bill Code List'!$P:$P,MATCH(A8,'[5]Combined Bill Code List'!$F:$F,0)) -> 0 | AD8: CLASS | AE8: 1 | AF8: 0 | AG8: =ROUND(INDEX('All Trends'!D:D,MATCH($AD8,'All Trends'!$C:$C,0)),4) -> 0.9708 | AH8: =ROUND(INDEX('All Trends'!E:E,MATCH($AD8,'All Trends'!$C:$C,0)),4) -> 1.003 | AI8: =ROUND(INDEX('All Trends'!F:F,MATCH($AD8,'All Trends'!$C:$C,0)),4) -> 1.0231 | AJ8: =ROUND(INDEX('All Trends'!G:G,MATCH($AD8,'All Trends'!$C:$C,0)),4) -> 1.0231 | AK8: =ROUND(INDEX('All Trends'!H:H,MATCH($AD8,'All Trends'!$C:$C,0)),4) -> 1.0231 | AL8: No | AM8: =IF(C8="Yes",ROUND(T8*N8*AI8,2),0) -> 340186.36 | AN8: =IF(C8="Yes",ROUND(T8*N8*AJ8,2),0) -> 340186.36 | AO8: =IF(C8="Yes",ROUND((W8*N8*AI8),2),0) -> 0 | AP8: =IF(C8="Yes",IF($AL8="No",ROUND(($AO8*($AY$2+$AF8)),2),ROUND($AO8,2)),0) -> 0 | AQ8: =IF(C8="Yes",ROUND((W8*N8*AJ8),2),0) -> 0 | AR8: =IF(C8="Yes",IF($AL8="No",ROUND(($AQ8*($AZ$2+$AF8)),2),ROUND($AQ8,2)),0) -> 0
A9: 210CFCG1108 | B9: 210CFCG1108 | C9: Yes | D9: No | E9: CLASS | F9: PAS/HAB | G9: =INDEX('[4]RT Description to Bill Matix'!$D:$D,MATCH(A9,'[4]RT Description to Bill Matix'!$M:$M,0)) -> PAS/HAB (CFC) | H9: CFC PAS/HAB | J9: {=INDEX('Rate Table Service Desc XWalk'!F:F,MATCH(1,(G9='Rate Table Service Desc XWalk'!B:B)*(E9='Rate Table Service Desc XWalk'!A:A),0))} -> 1-1-78 | K9: =INDEX('[5]Combined Bill Code List'!$A:$A,MATCH(A9,'[5]Combined Bill Code List'!$F:$F,0)) -> State Plan (Title XIX) | L9: =INDEX('[6]Rate History'!$P:$P,MATCH(A9,'[6]Rate History'!$F:$F,0)) -> 1 hour | M9: =INDEX('[7]PDF DB Service Pivot'!$C:$C,MATCH(B9,'[7]PDF DB Service Pivot'!$B:$B,0)) -> 8801962.1 | N9: =IF(ISNUMBER(FIND("ISS",F9)),IF(I9="Yes",((M9/Q9)/6)*12,(M9/6)*12),IF(AND(I9="Yes",M9=O9),M9/Q9,M9)) -> 8801962.1 | O9: =INDEX('[7]PDF DB Service Pivot'!$D:$D,MATCH(B9,'[7]PDF DB Service Pivot'!$B:$B,0)) -> 1.3646574e+08 | P9: 45170 | Q9: 14.96 | R9: 11.75 | S9: =_xlfn.IFNA(R9/Q9,"") -> 0.78542781 | T9: =INDEX('[8]Billable Services'!$P:$P,MATCH(B9,'[8]Billable Services'!$S:$S,0)) -> 1 | U9: =ROUND(V9/Z9,2) -> 0 | V9: {=_xlfn.IFS('Fiscal by Program'!$B$7<10.61,0,'Fiscal by Program'!$B$7>10.6,(ROUND('Fiscal by Program'!$B$7*(1+IF(D9="Yes",'Fiscal by Program'!$B$9,'Fiscal by Program'!$B$8))*T9,2)))} -> 0 | W9: =IF(V9-R9<0,0,V9-R9) -> 0 | X9: =ROUND((R9/(1+IF(D9="Yes",'Fiscal by Program'!$B$9,'Fiscal by Program'!$B$8))),2)+0.01 -> 10.62 | Y9: =Q9+W9 -> 14.96 | Z9: 4 | AA9: =T9/Z9 -> 0.25 | AB9: =INDEX('[9]Service List'!$K:$K,MATCH(A9,'[9]Service List'!$F:$F,0)) -> 53 | AC9: CFC | AD9: CLASS | AE9: 1 | AF9: -0.06 | AG9: =ROUND(INDEX('All Trends'!D:D,MATCH($AD9,'All Trends'!$C:$C,0)),4) -> 0.9708 | AH9: =ROUND(INDEX('All Trends'!E:E,MATCH($AD9,'All Trends'!$C:$C,0)),4) -> 1.003 | AI9: =ROUND(INDEX('All Trends'!F:F,MATCH($AD9,'All Trends'!$C:$C,0)),4) -> 1.0231 | AJ9: =ROUND(INDEX('All Trends'!G:G,MATCH($AD9,'All Trends'!$C:$C,0)),4) -> 1.0231 | AK9: =ROUND(INDEX('All Trends'!H:H,MATCH($AD9,'All Trends'!$C:$C,0)),4) -> 1.0231 | AL9: No | AM9: =IF(C9="Yes",ROUND(T9*N9*AI9,2),0) -> 9005287.4 | AN9: =IF(C9="Yes",ROUND(T9*N9*AJ9,2),0) -> 9005287.4 | AO9: =IF(C9="Yes",ROUND((W9*N9*AI9),2),0) -> 0 | AP9: =IF(C9="Yes",IF($AL9="No",ROUND(($AO9*($AY$2+$AF9)),2),ROUND($AO9,2)),0) -> 0 | AQ9: =IF(C9="Yes",ROUND((W9*N9*AJ9),2),0) -> 0 | AR9: =IF(C9="Yes",IF($AL9="No",ROUND(($AQ9*($AZ$2+$AF9)),2),ROUND($AQ9,2)),0) -> 0
A10: 210CFVG1109 | B10: 210CFVG1109 | C10: Yes | D10: No | E10: CLASS | F10: PAS/HAB | G10: =INDEX('[4]RT Description to Bill Matix'!$D:$D,MATCH(A10,'[4]RT Description to Bill Matix'!$M:$M,0)) -> CDS PAS/HAB (CFC) | H10: CFC PAS/HAB (CDS) | I10: Yes | J10: {=INDEX('Rate Table Service Desc XWalk'!F:F,MATCH(1,(G10='Rate Table Service Desc XWalk'!B:B)*(E10='Rate Table Service Desc XWalk'!A:A),0))} -> 1-5-142 | K10: =INDEX('[5]Combined Bill Code List'!$A:$A,MATCH(A10,'[5]Combined Bill Code List'!$F:$F,0)) -> State Plan (Title XIX) | L10: =INDEX('[6]Rate History'!$P:$P,MATCH(A10,'[6]Rate History'!$F:$F,0)) -> 1 hour | M10: =INDEX('[7]PDF DB Service Pivot'!$C:$C,MATCH(B10,'[7]PDF DB Service Pivot'!$B:$B,0)) -> 87110157 | N10: =IF(ISNUMBER(FIND("ISS",F10)),IF(I10="Yes",((M10/Q10)/6)*12,(M10/6)*12),IF(AND(I10="Yes",M10=O10),M10/Q10,M10)) -> 6151847.2 | O10: =INDEX('[7]PDF DB Service Pivot'!$D:$D,MATCH(B10,'[7]PDF DB Service Pivot'!$B:$B,0)) -> 87110157 | P10: 45170 | Q10: 14.16 | R10: 11.75 | S10: =_xlfn.IFNA(R10/Q10,"") -> 0.82980226 | T10: 1 | U10: =ROUND(V10/Z10,2) -> 0 | V10: {=_xlfn.IFS('Fiscal by Program'!$B$7<10.61,0,'Fiscal by Program'!$B$7>10.6,(ROUND('Fiscal by Program'!$B$7*(1+IF(D10="Yes",'Fiscal by Program'!$B$9,'Fiscal by Program'!$B$8))*T10,2)))} -> 0 | W10: =IF(V10-R10<0,0,V10-R10) -> 0 | X10: =ROUND((R10/(1+IF(D10="Yes",'Fiscal by Program'!$B$9,'Fiscal by Program'!$B$8))),2)+0.01 -> 10.62 | Y10: =Q10+W10 -> 14.16 | Z10: 4 | AA10: =T10/Z10 -> 0.25 | AB10: =INDEX('[9]Service List'!$K:$K,MATCH(A10,'[9]Service List'!$F:$F,0)) -> 52 | AC10: CFC | AD10: CLASS | AE10: 1 | AF10: -0.06 | AG10: =ROUND(INDEX('All Trends'!D:D,MATCH($AD10,'All Trends'!$C:$C,0)),4) -> 0.9708 | AH10: =ROUND(INDEX('All Trends'!E:E,MATCH($AD10,'All Trends'!$C:$C,0)),4) -> 1.003 | AI10: =ROUND(INDEX('All Trends'!F:F,MATCH($AD10,'All Trends'!$C:$C,0)),4) -> 1.0231 | AJ10: =ROUND(INDEX('All Trends'!G:G,MATCH($AD10,'All Trends'!$C:$C,0)),4) -> 1.0231 | AK10: =ROUND(INDEX('All Trends'!H:H,MATCH($AD10,'All Trends'!$C:$C,0)),4) -> 1.0231 | AL10: No | AM10: =IF(C10="Yes",ROUND(T10*N10*AI10,2),0) -> 6293954.9 | AN10: =IF(C10="Yes",ROUND(T10*N10*AJ10,2),0) -> 6293954.9 | AO10: =IF(C10="Yes",ROUND((W10*N10*AI10),2),0) -> 0 | AP10: =IF(C10="Yes",IF($AL10="No",ROUND(($AO10*($AY$2+$AF10)),2),ROUND($AO10,2)),0) -> 0 | AQ10: =IF(C10="Yes",ROUND((W10*N10*AJ10),2),0) -> 0 | AR10: =IF(C10="Yes",IF($AL10="No",ROUND(($AQ10*($AZ$2+$AF10)),2),ROUND($AQ10,2)),0) -> 0
A11: 211G0100 | B11: 211G0100 | C11: Yes | D11: No | E11: CLASS | F11: In Home Respite | G11: =INDEX('[4]RT Description to Bill Matix'!$D:$D,MATCH(A11,'[4]RT Description to Bill Matix'!$M:$M,0)) -> In Home Respite | H11: RESPITE-IN HOME RESPITE-DSA | J11: {=INDEX('Rate Table Service Desc XWalk'!F:F,MATCH(1,(G11='Rate Table Service Desc XWalk'!B:B)*(E11='Rate Table Service Desc XWalk'!A:A),0))} -> 1-1-55 | K11: =INDEX('[5]Combined Bill Code List'!$A:$A,MATCH(A11,'[5]Combined Bill Code List'!$F:$F,0)) -> 1915(c) waiver | L11: =INDEX('[6]Rate History'!$P:$P,MATCH(A11,'[6]Rate History'!$F:$F,0)) -> 1 day | M11: =INDEX('[7]PDF DB Service Pivot'!$C:$C,MATCH(B11,'[7]PDF DB Service Pivot'!$B:$B,0)) -> 22044.16 | N11: =IF(ISNUMBER(FIND("ISS",F11)),IF(I11="Yes",((M11/Q11)/6)*12,(M11/6)*12),IF(AND(I11="Yes",M11=O11),M11/Q11,M11)) -> 22044.16 | O11: =INDEX('[7]PDF DB Service Pivot'!$D:$D,MATCH(B11,'[7]PDF DB Service Pivot'!$B:$B,0)) -> 5323900.5 | P11: 45170 | Q11: 311.12 | R11: 281.78 | S11: =_xlfn.IFNA(R11/Q11,"") -> 0.90569555 | T11: 24 | U11: =ROUND(V11/Z11,2) -> 0 | V11: {=_xlfn.IFS('Fiscal by Program'!$B$7<10.61,0,'Fiscal by Program'!$B$7>10.6,(ROUND('Fiscal by Program'!$B$7*(1+IF(D11="Yes",'Fiscal by Program'!$B$9,'Fiscal by Program'!$B$8))*T11,2)))} -> 0 | W11: =IF(V11-R11<0,0,V11-R11) -> 0 | X11: =ROUND((R11/(1+IF(D11="Yes",'Fiscal by Program'!$B$9,'Fiscal by Program'!$B$8))),2)+0.01 -> 254.44 | Y11: =Q11+W11 -> 311.12 | Z11: 96 | AA11: =T11/Z11 -> 0.25 | AB11: =INDEX('[9]Service List'!$K:$K,MATCH(A11,'[9]Service List'!$F:$F,0)) -> 39 | AC11: =INDEX('[5]Combined Bill Code List'!$P:$P,MATCH(A11,'[5]Combined Bill Code List'!$F:$F,0)) -> 0 | AD11: CLASS | AE11: 1 | AF11: 0 | AG11: =ROUND(INDEX('All Trends'!D:D,MATCH($AD11,'All Trends'!$C:$C,0)),4) -> 0.9708 | AH11: =ROUND(INDEX('All Trends'!E:E,MATCH($AD11,'All Trends'!$C:$C,0)),4) -> 1.003 | AI11: =ROUND(INDEX('All Trends'!F:F,MATCH($AD11,'All Trends'!$C:$C,0)),4) -> 1.0231 | AJ11: =ROUND(INDEX('All Trends'!G:G,MATCH($AD11,'All Trends'!$C:$C,0)),4) -> 1.0231 | AK11: =ROUND(INDEX('All Trends'!H:H,MATCH($AD11,'All Trends'!$C:$C,0)),4) -> 1.0231 | AL11: No | AM11: =IF(C11="Yes",ROUND(T11*N11*AI11,2),0) -> 541281.12 | AN11: =IF(C11="Yes",ROUND(T11*N11*AJ11,2),0) -> 541281.12 | AO11: =IF(C11="Yes",ROUND((W11*N11*AI11),2),0) -> 0 | AP11: =IF(C11="Yes",IF($AL11="No",ROUND(($AO11*($AY$2+$AF11)),2),ROUND($AO11,2)),0) -> 0 | AQ11: =IF(C11="Yes",ROUND((W11*N11*AJ11),2),0) -> 0 | AR11: =IF(C11="Yes",IF($AL11="No",ROUND(($AQ11*($AZ$2+$AF11)),2),ROUND($AQ11,2)),0) -> 0
A12: 211PVG0197 | B12: 211PVG0197 | C12: Yes | D12: No | E12: CLASS | F12: In Home Respite | G12: =INDEX('[4]RT Description to Bill Matix'!$D:$D,MATCH(A12,'[4]RT Description to Bill Matix'!$M:$M,0)) -> CDS In Home Respite | H12: RESPITE IN-HOME (CDS) | I12: Yes | J12: {=INDEX('Rate Table Service Desc XWalk'!F:F,MATCH(1,(G12='Rate Table Service Desc XWalk'!B:B)*(E12='Rate Table Service Desc XWalk'!A:A),0))} -> 1-5-136 | K12: =INDEX('[5]Combined Bill Code List'!$A:$A,MATCH(A12,'[5]Combined Bill Code List'!$F:$F,0)) -> 1915(c) waiver | L12: =INDEX('[6]Rate History'!$P:$P,MATCH(A12,'[6]Rate History'!$F:$F,0)) -> 1 day | M12: =INDEX('[7]PDF DB Service Pivot'!$C:$C,MATCH(B12,'[7]PDF DB Service Pivot'!$B:$B,0)) -> 5354163.9 | N12: =IF(ISNUMBER(FIND("ISS",F12)),IF(I12="Yes",((M12/Q12)/6)*12,(M12/6)*12),IF(AND(I12="Yes",M12=O12),M12/Q12,M12)) -> 18647.826 | O12: =INDEX('[7]PDF DB Service Pivot'!$D:$D,MATCH(B12,'[7]PDF DB Service Pivot'!$B:$B,0)) -> 5354163.9 | P12: 45170 | Q12: 287.12 | R12: 281.78 | S12: =_xlfn.IFNA(R12/Q12,"") -> 0.9814015 | T12: 24 | U12: =ROUND(V12/Z12,2) -> 0 | V12: {=_xlfn.IFS('Fiscal by Program'!$B$7<10.61,0,'Fiscal by Program'!$B$7>10.6,(ROUND('Fiscal by Program'!$B$7*(1+IF(D12="Yes",'Fiscal by Program'!$B$9,'Fiscal by Program'!$B$8))*T12,2)))} -> 0 | W12: =IF(V12-R12<0,0,V12-R12) -> 0 | X12: =ROUND((R12/(1+IF(D12="Yes",'Fiscal by Program'!$B$9,'Fiscal by Program'!$B$8))),2)+0.01 -> 254.44 | Y12: =Q12+W12 -> 287.12 | Z12: 96 | AA12: =T12/Z12 -> 0.25 | AB12: =INDEX('[9]Service List'!$K:$K,MATCH(A12,'[9]Service List'!$F:$F,0)) -> 38 | AC12: =INDEX('[5]Combined Bill Code List'!$P:$P,MATCH(A12,'[5]Combined Bill Code List'!$F:$F,0)) -> 0 | AD12: CLASS | AE12: 1 | AF12: 0 | AG12: =ROUND(INDEX('All Trends'!D:D,MATCH($AD12,'All Trends'!$C:$C,0)),4) -> 0.9708 | AH12: =ROUND(INDEX('All Trends'!E:E,MATCH($AD12,'All Trends'!$C:$C,0)),4) -> 1.003 | AI12: =ROUND(INDEX('All Trends'!F:F,MATCH($AD12,'All Trends'!$C:$C,0)),4) -> 1.0231 | AJ12: =ROUND(INDEX('All Trends'!G:G,MATCH($AD12,'All Trends'!$C:$C,0)),4) -> 1.0231 | AK12: =ROUND(INDEX('All Trends'!H:H,MATCH($AD12,'All Trends'!$C:$C,0)),4) -> 1.0231 | AL12: No | AM12: =IF(C12="Yes",ROUND(T12*N12*AI12,2),0) -> 457886.18 | AN12: =IF(C12="Yes",ROUND(T12*N12*AJ12,2),0) -> 457886.18 | AO12: =IF(C12="Yes",ROUND((W12*N12*AI12),2),0) -> 0 | AP12: =IF(C12="Yes",IF($AL12="No",ROUND(($AO12*($AY$2+$AF12)),2),ROUND($AO12,2)),0) -> 0 | AQ12: =IF(C12="Yes",ROUND((W12*N12*AJ12),2),0) -> 0 | AR12: =IF(C12="Yes",IF($AL12="No",ROUND(($AQ12*($AZ$2+$AF12)),2),ROUND($AQ12,2)),0) -> 0
A13: 237H2025 | B13: 237H2025 | C13: Yes | D13: No | E13: CLASS | F13: Employment Services | G13: =INDEX('[4]RT Description to Bill Matix'!$D:$D,MATCH(A13,'[4]RT Description to Bill Matix'!$M:$M,0)) -> Employment Assistance and Supported Employment | H13: CLASS SUPPORTED EMPLOYMENT (AO) | J13: {=INDEX('Rate Table Service Desc XWalk'!F:F,MATCH(1,(G13='Rate Table Service Desc XWalk'!B:B)*(E13='Rate Table Service Desc XWalk'!A:A),0))} -> 1-1-23 | K13: =INDEX('[5]Combined Bill Code List'!$A:$A,MATCH(A13,'[5]Combined Bill Code List'!$F:$F,0)) -> 1915(c) waiver | L13: =INDEX('[6]Rate History'!$P:$P,MATCH(A13,'[6]Rate History'!$F:$F,0)) -> 1 hour | M13: =INDEX('[7]PDF DB Service Pivot'!$C:$C,MATCH(B13,'[7]PDF DB Service Pivot'!$B:$B,0)) -> 696 | N13: =IF(ISNUMBER(FIND("ISS",F13)),IF(I13="Yes",((M13/Q13)/6)*12,(M13/6)*12),IF(AND(I13="Yes",M13=O13),M13/Q13,M13)) -> 696 | O13: =INDEX('[7]PDF DB Service Pivot'!$D:$D,MATCH(B13,'[7]PDF DB Service Pivot'!$B:$B,0)) -> 19362.72 | P13: 41518 | Q13: 26.07 | R13: 19.07 | S13: =_xlfn.IFNA(R13/Q13,"") -> 0.73149214 | T13: =INDEX('[8]Billable Services'!$P:$P,MATCH(B13,'[8]Billable Services'!$S:$S,0)) -> 1 | U13: =ROUND(V13/Z13,2) -> 0 | V13: {=_xlfn.IFS('Fiscal by Program'!$B$7<10.61,0,'Fiscal by Program'!$B$7>10.6,(ROUND('Fiscal by Program'!$B$7*(1+IF(D13="Yes",'Fiscal by Program'!$B$9,'Fiscal by Program'!$B$8))*T13,2)))} -> 0 | W13: =IF(V13-R13<0,0,V13-R13) -> 0 | X13: =ROUND((R13/(1+IF(D13="Yes",'Fiscal by Program'!$B$9,'Fiscal by Program'!$B$8))),2)+0.01 -> 17.23 | Y13: =Q13+W13 -> 26.07 | Z13: 4 | AA13: =T13/Z13 -> 0.25 | AB13: =INDEX('[9]Service List'!$K:$K,MATCH(A13,'[9]Service List'!$F:$F,0)) -> 24 | AC13: =INDEX('[5]Combined Bill Code List'!$P:$P,MATCH(A13,'[5]Combined Bill Code List'!$F:$F,0)) -> 0 | AD13: CLASS | AE13: 1 | AF13: 0 | AG13: =ROUND(INDEX('All Trends'!D:D,MATCH($AD13,'All Trends'!$C:$C,0)),4) -> 0.9708 | AH13: =ROUND(INDEX('All Trends'!E:E,MATCH($AD13,'All Trends'!$C:$C,0)),4) -> 1.003 | AI13: =ROUND(INDEX('All Trends'!F:F,MATCH($AD13,'All Trends'!$C:$C,0)),4) -> 1.0231 | AJ13: =ROUND(INDEX('All Trends'!G:G,MATCH($AD13,'All Trends'!$C:$C,0)),4) -> 1.0231 | AK13: =ROUND(INDEX('All Trends'!H:H,MATCH($AD13,'All Trends'!$C:$C,0)),4) -> 1.0231 | AL13: No | AM13: =IF(C13="Yes",ROUND(T13*N13*AI13,2),0) -> 712.08 | AN13: =IF(C13="Yes",ROUND(T13*N13*AJ13,2),0) -> 712.08 | AO13: =IF(C13="Yes",ROUND((W13*N13*AI13),2),0) -> 0 | AP13: =IF(C13="Yes",IF($AL13="No",ROUND(($AO13*($AY$2+$AF13)),2),ROUND($AO13,2)),0) -> 0 | AQ13: =IF(C13="Yes",ROUND((W13*N13*AJ13),2),0) -> 0 | AR13: =IF(C13="Yes",IF($AL13="No",ROUND(($AQ13*($AZ$2+$AF13)),2),ROUND($AQ13,2)),0) -> 0
A14: 237VH2027 | B14: 237VH2027 | C14: Yes | D14: No | E14: CLASS | F14: Employment Services | G14: =INDEX('[4]RT Description to Bill Matix'!$D:$D,MATCH(A14,'[4]RT Description to Bill Matix'!$M:$M,0)) -> CDS Employment Assistance and Supported Employment | H14: CLASS (CDS) -SUPPORTED EMPLOYMENT | I14: Yes | J14: {=INDEX('Rate Table Service Desc XWalk'!F:F,MATCH(1,(G14='Rate Table Service Desc XWalk'!B:B)*(E14='Rate Table Service Desc XWalk'!A:A),0))} -> 1-5-121 | K14: =INDEX('[5]Combined Bill Code List'!$A:$A,MATCH(A14,'[5]Combined Bill Code List'!$F:$F,0)) -> 1915(c) waiver | L14: =INDEX('[6]Rate History'!$P:$P,MATCH(A14,'[6]Rate History'!$F:$F,0)) -> 1 hour | M14: =INDEX('[7]PDF DB Service Pivot'!$C:$C,MATCH(B14,'[7]PDF DB Service Pivot'!$B:$B,0)) -> 260896.24 | N14: =IF(ISNUMBER(FIND("ISS",F14)),IF(I14="Yes",((M14/Q14)/6)*12,(M14/6)*12),IF(AND(I14="Yes",M14=O14),M14/Q14,M14)) -> 10324.347 | O14: =INDEX('[7]PDF DB Service Pivot'!$D:$D,MATCH(B14,'[7]PDF DB Service Pivot'!$B:$B,0)) -> 260896.24 | P14: 41518 | Q14: 25.27 | R14: 18.484806 | S14: =_xlfn.IFNA(R14/Q14,"") -> 0.73149214 | T14: 1 | U14: =ROUND(V14/Z14,2) -> 0 | V14: {=_xlfn.IFS('Fiscal by Program'!$B$7<10.61,0,'Fiscal by Program'!$B$7>10.6,(ROUND('Fiscal by Program'!$B$7*(1+IF(D14="Yes",'Fiscal by Program'!$B$9,'Fiscal by Program'!$B$8))*T14,2)))} -> 0 | W14: =IF(V14-R14<0,0,V14-R14) -> 0 | X14: =ROUND((R14/(1+IF(D14="Yes",'Fiscal by Program'!$B$9,'Fiscal by Program'!$B$8))),2)+0.01 -> 16.7 | Y14: =Q14+W14 -> 25.27 | Z14: 4 | AA14: =T14/Z14 -> 0.25 | AB14: =INDEX('[9]Service List'!$K:$K,MATCH(A14,'[9]Service List'!$F:$F,0)) -> 23 | AC14: =INDEX('[5]Combined Bill Code List'!$P:$P,MATCH(A14,'[5]Combined Bill Code List'!$F:$F,0)) -> 0 | AD14: CLASS | AE14: 1 | AF14: 0 | AG14: =ROUND(INDEX('All Trends'!D:D,MATCH($AD14,'All Trends'!$C:$C,0)),4) -> 0.9708 | AH14: =ROUND(INDEX('All Trends'!E:E,MATCH($AD14,'All Trends'!$C:$C,0)),4) -> 1.003 | AI14: =ROUND(INDEX('All Trends'!F:F,MATCH($AD14,'All Trends'!$C:$C,0)),4) -> 1.0231 | AJ14: =ROUND(INDEX('All Trends'!G:G,MATCH($AD14,'All Trends'!$C:$C,0)),4) -> 1.0231 | AK14: =ROUND(INDEX('All Trends'!H:H,MATCH($AD14,'All Trends'!$C:$C,0)),4) -> 1.0231 | AL14: No | AM14: =IF(C14="Yes",ROUND(T14*N14*AI14,2),0) -> 10562.84 | AN14: =IF(C14="Yes",ROUND(T14*N14*AJ14,2),0) -> 10562.84 | AO14: =IF(C14="Yes",ROUND((W14*N14*AI14),2),0) -> 0 | AP14: =IF(C14="Yes",IF($AL14="No",ROUND(($AO14*($AY$2+$AF14)),2),ROUND($AO14,2)),0) -> 0 | AQ14: =IF(C14="Yes",ROUND((W14*N14*AJ14),2),0) -> 0 | AR14: =IF(C14="Yes",IF($AL14="No",ROUND(($AQ14*($AZ$2+$AF14)),2),ROUND($AQ14,2)),0) -> 0
A15: 248G0248 | B15: 248G0248 | C15: Yes | D15: No | E15: CLASS | F15: PAS/HAB | G15: =INDEX('[4]RT Description to Bill Matix'!$D:$D,MATCH(A15,'[4]RT Description to Bill Matix'!$M:$M,0)) -> Habilitation | H15: HAB TRANSPORTATION | J15: {=INDEX('Rate Table Service Desc XWalk'!F:F,MATCH(1,(G15='Rate Table Service Desc XWalk'!B:B)*(E15='Rate Table Service Desc XWalk'!A:A),0))} -> 1-1-26 | K15: =INDEX('[5]Combined Bill Code List'!$A:$A,MATCH(A15,'[5]Combined Bill Code List'!$F:$F,0)) -> 1915(c) waiver | L15: =INDEX('[6]Rate History'!$P:$P,MATCH(A15,'[6]Rate History'!$F:$F,0)) -> 1 hour | M15: =INDEX('[7]PDF DB Service Pivot'!$C:$C,MATCH(B15,'[7]PDF DB Service Pivot'!$B:$B,0)) -> 3931.65 | N15: =IF(ISNUMBER(FIND("ISS",F15)),IF(I15="Yes",((M15/Q15)/6)*12,(M15/6)*12),IF(AND(I15="Yes",M15=O15),M15/Q15,M15)) -> 3931.65 | O15: =INDEX('[7]PDF DB Service Pivot'!$D:$D,MATCH(B15,'[7]PDF DB Service Pivot'!$B:$B,0)) -> 60328.66 | P15: 45170 | Q15: 14.96 | R15: 11.75 | S15: =_xlfn.IFNA(R15/Q15,"") -> 0.78542781 | T15: =INDEX('[8]Billable Services'!$P:$P,MATCH(B15,'[8]Billable Services'!$S:$S,0)) -> 1 | U15: =ROUND(V15/Z15,2) -> 0 | V15: {=_xlfn.IFS('Fiscal by Program'!$B$7<10.61,0,'Fiscal by Program'!$B$7>10.6,(ROUND('Fiscal by Program'!$B$7*(1+IF(D15="Yes",'Fiscal by Program'!$B$9,'Fiscal by Program'!$B$8))*T15,2)))} -> 0 | W15: =IF(V15-R15<0,0,V15-R15) -> 0 | X15: =ROUND((R15/(1+IF(D15="Yes",'Fiscal by Program'!$B$9,'Fiscal by Program'!$B$8))),2)+0.01 -> 10.62 | Y15: =Q15+W15 -> 14.96 | Z15: 4 | AA15: =T15/Z15 -> 0.25 | AB15: =INDEX('[9]Service List'!$K:$K,MATCH(A15,'[9]Service List'!$F:$F,0)) -> 35 | AC15: =INDEX('[5]Combined Bill Code List'!$P:$P,MATCH(A15,'[5]Combined Bill Code List'!$F:$F,0)) -> 0 | AD15: CLASS | AE15: 1 | AF15: 0 | AG15: =ROUND(INDEX('All Trends'!D:D,MATCH($AD15,'All Trends'!$C:$C,0)),4) -> 0.9708 | AH15: =ROUND(INDEX('All Trends'!E:E,MATCH($AD15,'All Trends'!$C:$C,0)),4) -> 1.003 | AI15: =ROUND(INDEX('All Trends'!F:F,MATCH($AD15,'All Trends'!$C:$C,0)),4) -> 1.0231 | AJ15: =ROUND(INDEX('All Trends'!G:G,MATCH($AD15,'All Trends'!$C:$C,0)),4) -> 1.0231 | AK15: =ROUND(INDEX('All Trends'!H:H,MATCH($AD15,'All Trends'!$C:$C,0)),4) -> 1.0231 | AL15: No | AM15: =IF(C15="Yes",ROUND(T15*N15*AI15,2),0) -> 4022.47 | AN15: =IF(C15="Yes",ROUND(T15*N15*AJ15,2),0) -> 4022.47 | AO15: =IF(C15="Yes",ROUND((W15*N15*AI15),2),0) -> 0 | AP15: =IF(C15="Yes",IF($AL15="No",ROUND(($AO15*($AY$2+$AF15)),2),ROUND($AO15,2)),0) -> 0 | AQ15: =IF(C15="Yes",ROUND((W15*N15*AJ15),2),0) -> 0 | AR15: =IF(C15="Yes",IF($AL15="No",ROUND(($AQ15*($AZ$2+$AF15)),2),ROUND($AQ15,2)),0) -> 0
A16: 248VG0249 | B16: 248VG0249 | C16: Yes | D16: No | E16: CLASS | F16: PAS/HAB | G16: =INDEX('[4]RT Description to Bill Matix'!$D:$D,MATCH(A16,'[4]RT Description to Bill Matix'!$M:$M,0)) -> CDS Habilitation | H16: HAB TRANSPORTATION (CDS) | I16: Yes | J16: {=INDEX('Rate Table Service Desc XWalk'!F:F,MATCH(1,(G16='Rate Table Service Desc XWalk'!B:B)*(E16='Rate Table Service Desc XWalk'!A:A),0))} -> 1-5-122 | K16: =INDEX('[5]Combined Bill Code List'!$A:$A,MATCH(A16,'[5]Combined Bill Code List'!$F:$F,0)) -> 1915(c) waiver | L16: =INDEX('[6]Rate History'!$P:$P,MATCH(A16,'[6]Rate History'!$F:$F,0)) -> 1 hour | M16: =INDEX('[7]PDF DB Service Pivot'!$C:$C,MATCH(B16,'[7]PDF DB Service Pivot'!$B:$B,0)) -> 171886.79 | N16: =IF(ISNUMBER(FIND("ISS",F16)),IF(I16="Yes",((M16/Q16)/6)*12,(M16/6)*12),IF(AND(I16="Yes",M16=O16),M16/Q16,M16)) -> 12138.898 | O16: =INDEX('[7]PDF DB Service Pivot'!$D:$D,MATCH(B16,'[7]PDF DB Service Pivot'!$B:$B,0)) -> 171886.79 | P16: 45170 | Q16: 14.16 | R16: 11.75 | S16: =_xlfn.IFNA(R16/Q16,"") -> 0.82980226 | T16: 1 | U16: =ROUND(V16/Z16,2) -> 0 | V16: {=_xlfn.IFS('Fiscal by Program'!$B$7<10.61,0,'Fiscal by Program'!$B$7>10.6,(ROUND('Fiscal by Program'!$B$7*(1+IF(D16="Yes",'Fiscal by Program'!$B$9,'Fiscal by Program'!$B$8))*T16,2)))} -> 0 | W16: =IF(V16-R16<0,0,V16-R16) -> 0 | X16: =ROUND((R16/(1+IF(D16="Yes",'Fiscal by Program'!$B$9,'Fiscal by Program'!$B$8))),2)+0.01 -> 10.62 | Y16: =Q16+W16 -> 14.16 | Z16: 4 | AA16: =T16/Z16 -> 0.25 | AB16: =INDEX('[9]Service List'!$K:$K,MATCH(A16,'[9]Service List'!$F:$F,0)) -> 33 | AC16: =INDEX('[5]Combined Bill Code List'!$P:$P,MATCH(A16,'[5]Combined Bill Code List'!$F:$F,0)) -> 0 | AD16: CLASS | AE16: 1 | AF16: 0 | AG16: =ROUND(INDEX('All Trends'!D:D,MATCH($AD16,'All Trends'!$C:$C,0)),4) -> 0.9708 | AH16: =ROUND(INDEX('All Trends'!E:E,MATCH($AD16,'All Trends'!$C:$C,0)),4) -> 1.003 | AI16: =ROUND(INDEX('All Trends'!F:F,MATCH($AD16,'All Trends'!$C:$C,0)),4) -> 1.0231 | AJ16: =ROUND(INDEX('All Trends'!G:G,MATCH($AD16,'All Trends'!$C:$C,0)),4) -> 1.0231 | AK16: =ROUND(INDEX('All Trends'!H:H,MATCH($AD16,'All Trends'!$C:$C,0)),4) -> 1.0231 | AL16: No | AM16: =IF(C16="Yes",ROUND(T16*N16*AI16,2),0) -> 12419.31 | AN16: =IF(C16="Yes",ROUND(T16*N16*AJ16,2),0) -> 12419.31 | AO16: =IF(C16="Yes",ROUND((W16*N16*AI16),2),0) -> 0 | AP16: =IF(C16="Yes",IF($AL16="No",ROUND(($AO16*($AY$2+$AF16)),2),ROUND($AO16,2)),0) -> 0 | AQ16: =IF(C16="Yes",ROUND((W16*N16*AJ16),2),0) -> 0 | AR16: =IF(C16="Yes",IF($AL16="No",ROUND(($AQ16*($AZ$2+$AF16)),2),ROUND($AQ16,2)),0) -> 0
A17: 729AC0202 | B17: 729AC0202 | C17: Yes | D17: Yes | E17: DAHS | F17: DAHS | G17: =INDEX('[4]RT Description to Bill Matix'!$D:$D,MATCH(A17,'[4]RT Description to Bill Matix'!$M:$M,0)) -> Day Activity and Health Services (DAHS) Title XIX and Title XX | H17: DAY ACTIVITY/HEALTH SERVICES (DAHS) TITLE XX | J17: {=INDEX('Rate Table Service Desc XWalk'!F:F,MATCH(1,(G17='Rate Table Service Desc XWalk'!B:B)*(E17='Rate Table Service Desc XWalk'!A:A),0))} -> 10-1-18 | K17: =INDEX('[5]Combined Bill Code List'!$A:$A,MATCH(A17,'[5]Combined Bill Code List'!$F:$F,0)) -> Title XX | L17: =INDEX('[6]Rate History'!$P:$P,MATCH(A17,'[6]Rate History'!$F:$F,0)) -> 3-5 hours = 1 unit; 6+ hours = 2 units | M17: =INDEX('[7]PDF DB Service Pivot'!$C:$C,MATCH(B17,'[7]PDF DB Service Pivot'!$B:$B,0)) -> 776159.03 | N17: =IF(ISNUMBER(FIND("ISS",F17)),IF(I17="Yes",((M17/Q17)/6)*12,(M17/6)*12),IF(AND(I17="Yes",M17=O17),M17/Q17,M17)) -> 776159.03 | O17: =INDEX('[7]PDF DB Service Pivot'!$D:$D,MATCH(B17,'[7]PDF DB Service Pivot'!$B:$B,0)) -> 12282455 | P17: 45170 | Q17: 16.72 | R17: 5.87 | S17: =_xlfn.IFNA(R17/Q17,"") -> 0.35107656 | T17: 0.5 | U17: =ROUND(V17/Z17,2) -> 0 | V17: {=_xlfn.IFS('Fiscal by Program'!$B$7<10.61,0,'Fiscal by Program'!$B$7>10.6,(ROUND('Fiscal by Program'!$B$7*(1+IF(D17="Yes",'Fiscal by Program'!$B$9,'Fiscal by Program'!$B$8))*T17,2)))} -> 0 | W17: =IF(V17-R17<0,0,V17-R17) -> 0 | X17: =ROUND((R17/(1+IF(D17="Yes",'Fiscal by Program'!$B$9,'Fiscal by Program'!$B$8))),2)+0.01 -> 5.31 | Y17: =Q17+W17 -> 16.72 | Z17: 16 | AA17: =T17/Z17 -> 0.03125 | AB17: =INDEX('[9]Service List'!$K:$K,MATCH(A17,'[9]Service List'!$F:$F,0)) -> 82 | AC17: =INDEX('[5]Combined Bill Code List'!$P:$P,MATCH(A17,'[5]Combined Bill Code List'!$F:$F,0)) -> 0 | AD17: Title XX Flat | AE17: 1 | AF17: 0 | AG17: =ROUND(INDEX('All Trends'!D:D,MATCH($AD17,'All Trends'!$C:$C,0)),4) -> 1 | AH17: =ROUND(INDEX('All Trends'!E:E,MATCH($AD17,'All Trends'!$C:$C,0)),4) -> 1 | AI17: =ROUND(INDEX('All Trends'!F:F,MATCH($AD17,'All Trends'!$C:$C,0)),4) -> 1 | AJ17: =ROUND(INDEX('All Trends'!G:G,MATCH($AD17,'All Trends'!$C:$C,0)),4) -> 1 | AK17: =ROUND(INDEX('All Trends'!H:H,MATCH($AD17,'All Trends'!$C:$C,0)),4) -> 1 | AL17: Yes | AM17: =IF(C17="Yes",ROUND(T17*N17*AI17,2),0) -> 388079.52 | AN17: =IF(C17="Yes",ROUND(T17*N17*AJ17,2),0) -> 388079.52 | AO17: =IF(C17="Yes",ROUND((W17*N17*AI17),2),0) -> 0 | AP17: =IF(C17="Yes",IF($AL17="No",ROUND(($AO17*($AY$2+$AF17)),2),ROUND($AO17,2)),0) -> 0 | AQ17: =IF(C17="Yes",ROUND((W17*N17*AJ17),2),0) -> 0 | AR17: =IF(C17="Yes",IF($AL17="No",ROUND(($AQ17*($AZ$2+$AF17)),2),ROUND($AQ17,2)),0) -> 0
